Workbook
Name AckDays: Lists!$B$4
Name AmberDays: Lists!$B$6
Name HighScore: Lists!$B$9
Name Holidays: tblHolidays[Holiday_Date]
Name IDPromptDays: Lists!$B$5
Name InternalDays: Lists!$B$3
Name L_ActionStatus: Lists!$U$2:$U$4
Name L_Approver: Lists!$AF$2:$AF$4
Name L_Area: Lists!$N$2:$N$7
Name L_Channel: Lists!$L$2:$L$6
Name L_Consult: Lists!$AE$2:$AE$5
Name L_DSRStatus: Lists!$O$2:$O$6
Name L_IncCat: Lists!$S$2:$S$3
Name L_IncStatus: Lists!$AG$2:$AG$3
Name L_IncType: Lists!$X$2:$X$15
Name L_Owner: Lists!$P$2:$P$7
Name L_ReqType: Lists!$H$2:$H$10
Name L_Requester: Lists!$M$2:$M$6
Name L_Risk: Lists!$R$2:$R$5
Name L_Score: Lists!$V$2:$V$6
Name L_SubjType: Lists!$T$2:$T$3
Name L_YesNo: Lists!$Q$2:$Q$3
Name MediumScore: Lists!$B$10
Name NotifyHours: Lists!$B$8
Name RedDays: Lists!$B$7
Name ReportDate: Lists!$B$2
Name ReqTypes: Lists!$H$2:$J$10
Name ReviewMonths: Lists!$B$11
Name SubjectBands: Lists!$Z$2:$AA$7
Name TimeBands: Lists!$AB$2:$AC$5

Sheet ReadMe
A1: GDPR Tracker - Northbay Retail Ltd (fictional)
A3: Purpose: an Excel tracker for the day-to-day work of a privacy team - logging data subject requests, tracking GDPR deadlines, recording personal data breaches and DPIAs, and producing a monthly report for the Data Privacy Manager.
A4: All register records are synthetic (incidents are modelled on real ICO records, see ICO_Template_Ref). Registers hold reference IDs only - no names, emails or other personal data (data minimisation).
A6: Sheets
A7: Lists - parameters (snapshot date, targets, thresholds), Irish public holidays (Excel table tblHolidays), lookup tables and dropdown lists, holiday checks
A8: DSR_Register - one row per request: statutory deadline with ID pause, extension and weekend/holiday roll-over, snapshot RAG, on-time flag, data check
A9: Incident_Log - one row per breach: notification decision, 72-hour deadline, time-to-report band, Art 34 flag, data check
A10: DPIA_Register - screening, inherent and residual risk, mitigation actions, automatic Art 36 flag kept separate from the recorded consultation and approval, review date, data check
A11: Live_Alerts - open requests, pending breach notifications and open DPIA actions ranked by urgency against TODAY()
A12: Monthly_Report - KPIs for a selected month (change cell B3), requests by type, six-month trend, data-check summary
A13: Benchmark - tracker figures next to DPC Annual Report 2025 and ICO retail incident data (ICO counts are live formulas)
A14: ICO_Retail_2024_25 - 2,831 real ICO incident records (UK, Retail and manufacture, 2024-2025), used by Benchmark and as templates for the synthetic incidents (Open Government Licence v3.0)
... A36: Built for Excel 2016 and later (EDATE, WORKDAY, NETWORKDAYS, VLOOKUP, INDEX, AGGREGATE, COUNTIFS, AVERAGEIFS; no dynamic arrays).

Sheet Lists
A1: Parameter | B1: Value | C1: Note | E1: Holiday_Date | F1: Holiday | H1: Request_Type | I1: Article | J1: Statutory | L1: Channel | M1: Requester_Type | N1: Business_Area | O1: DSR_Status | P1: Owner | Q1: Yes_No | R1: Risk_Level | S1: Incident_Category | T1: Data_Subject_Type | U1: Action_Status | V1: Score | X1: Incident_Type | Z1: Subjects_Min | AA1: Subjects_Band | AB1: Hours_Min | AC1: Time_Band | AE1: Consultation_Status | AF1: Approver | AG1: Incident_Status
A2: Report_Date | B2: 46325 | C2: SNAPSHOT date: register RAG/days columns and Monthly_Report are a historical snapshot as of this date (reproducible). Live_Alerts uses TODAY() instead. | E2: 46023 | F2: New Year's Day | H2: Access | I2: Art 15 | J2: Y | L2: Privacy mailbox | M2: Customer | N2: Online | O2: Logged | P2: Privacy Analyst | Q2: Y | R2: No risk | S2: Non Cyber | T2: Customers or prospective customers | U2: Open | V2: 1 | X2: Data emailed to incorrect recipient | Z2: 1 | AA2: 1 to 9 | AB2: 0 | AC2: Less than 24 hours | AE2: Not started | AF2: Data Privacy Manager | AG2: Open
A3: Internal_Target_Days | B3: 15 | C3: DPC recommends policies aimed at responding within 15 days (internal target) | E3: 46055 | F3: St Brigid's Day | H3: Rectification | I3: Art 16 | J3: Y | L3: Web form | M3: Employee | N3: Stores | O3: Awaiting ID | P3: Privacy Manager | Q3: N | R3: Low | S3: Cyber | T3: Employees | U3: In progress | V3: 2 | X3: Data posted or faxed to incorrect recipient | Z3: 10 | AA3: 10 to 99 | AB3: 24 | AC3: 24 hours to 72 hours | AE3: Submitted to DPC | AF3: Head of Legal | AG3: Closed
A4: Ack_Target_Working_Days | B4: 2 | C4: Internal policy: acknowledge within 2 working days | E4: 46098 | F4: St Patrick's Day | H4: Erasure | I4: Art 17 | J4: Y | L4: Post | M4: Former employee | N4: Loyalty & Marketing | O4: In progress | P4: HR | R4: Medium | U4: Done | V4: 3 | X4: Failure to use bcc | Z4: 100 | AA4: 100 to 1k | AB4: 72 | AC4: 72 hours to 1 week | AE4: DPC advice received | AF4: Business Owner
A5: ID_Request_Prompt_Days | B5: 3 | C5: Internal policy: ask for ID within 3 days so the pause is defensible (EDPB 01/2022 para 159) | E5: 46118 | F5: Easter Monday | H5: Restriction | I5: Art 18 | J5: Y | L5: In-store | M5: Job applicant | N5: HR | O5: Escalated | P5: IT | R5: High | V5: 4 | X5: Failure to redact | Z5: 1000 | AA5: 1k to 10k | AB5: 168 | AC5: More than 1 week | AE5: Not required
A6: Amber_Days | B6: 14 | C6: RAG: amber when 14 days or fewer remain | E6: 46146 | F6: May Bank Holiday | H6: Portability | I6: Art 20 | J6: Y | L6: Customer service | M6: Third party (authorised) | N6: CCTV & Security | O6: Closed | P6: Marketing | V6: 5 | X6: Verbal disclosure of personal data | Z6: 10000 | AA6: 10k to 100k
A7: Red_Days | B7: 7 | C7: RAG: red when 7 days or fewer remain | E7: 46174 | F7: June Bank Holiday | H7: Objection - direct marketing | I7: Art 21(2) | J7: Y | N7: Customer Service | P7: Store Operations | X7: Loss/theft of device containing personal data | Z7: 100000 | AA7: 100k and above
A8: Breach_Notify_Hours | B8: 72 | C8: GDPR Art 33(1): notify the DPC within 72 hours of becoming aware | E8: 46237 | F8: August Bank Holiday | H8: Objection - other | I8: Art 21(1) | J8: Y | X8: Loss/theft of paperwork or data left in insecure location
A9: High_Score | B9: 15 | C9: DPIA: likelihood x impact of 15-25 = High | E9: 46321 | F9: October Bank Holiday | H9: Complaint | I9: n/a | J9: N | X9: Data of wrong data subject shown in client portal
A10: Medium_Score | B10: 8 | C10: DPIA: 8-14 = Medium, below 8 = Low | E10: 46381 | F10: Christmas Day | H10: General query | I10: n/a | J10: N | X10: Unauthorised access
A11: DPIA_Review_Months | B11: 12 | C11: Internal policy: review approved DPIAs every 12 months | E11: 46382 | F11: St Stephen's Day (Saturday) | X11: Phishing
E12: 46388 | F12: New Year's Day | X12: Ransomware
A13: Holiday_List_Check | B13: =IF(COUNTA(tblHolidays[Holiday])=COUNT(tblHolidays[Holiday_Date]),"OK","Check: a holiday row has no valid date") -> OK | C13: Every holiday row must hold a real date | E13: 46419 | F13: St Brigid's Day | X13: Hardware/software misconfiguration
A14: Holidays_Covered_To | B14: =MAX(tblHolidays[Holiday_Date]) -> 46747 | C14: Last holiday in the list | E14: 46463 | F14: St Patrick's Day | X14: Other non-cyber incident
A15: Holiday_Coverage_Check | B15: =IF(MAX(DSR_Register!$U$2:$U$201)>B14,"Check: a deadline falls after "&TEXT(B14,"dd/mm/yyyy"),"OK") -> OK | C15: Warns when a deadline falls after the last listed holiday: add the next year | E15: 46475 | F15: Easter Monday | X15: Other cyber incident
E16: 46510 | F16: May Bank Holiday
E17: 46545 | F17: June Bank Holiday
E18: 46601 | F18: August Bank Holiday
E19: 46685 | F19: October Bank Holiday
E20: 46746 | F20: Christmas Day (Saturday)
E21: 46747 | F21: St Stephen's Day (Sunday)

Sheet DSR_Register
A1: Request_ID | B1: Received_Date | C1: Channel | D1: Request_Type | E1: Article | F1: Statutory | G1: Requester_Type | H1: Business_Area | I1: Acknowledged_Date | J1: Ack_On_Time | K1: ID_Check_Needed | L1: ID_Requested_Date | M1: ID_Received_Date | N1: ID_Request_Prompt | O1: Paused_Days | P1: Statutory_Deadline | Q1: Internal_Target | R1: Extended | S1: Extension_Notice_Date | T1: Extension_Notice_OK | U1: Final_Deadline | V1: Owner | W1: Status | X1: Escalated | Y1: Response_Date | Z1: Days_Open | AA1: Days_Remaining_Snapshot | AB1: RAG_Snapshot | AC1: On_Time | AD1: Exemption_Applied | AE1: Notes | AF1: Data_Check
A2: DSR-2026-001 | B2: 46146 | C2: Privacy mailbox | D2: Access | E2: =IF($A2="","",IFERROR(VLOOKUP($D2,ReqTypes,2,FALSE),"?")) -> Art 15 | F2: =IF($A2="","",IFERROR(VLOOKUP($D2,ReqTypes,3,FALSE),"?")) -> Y | G2: Customer | H2: Online | I2: 46147 | J2: =IF(OR($A2="",$I2=""),"",IF(NETWORKDAYS($B2,$I2,Holidays)-1<=AckDays,"Y","N")) -> Y | K2: N | N2: =IF(OR($A2="",$K2<>"Y"),"",IF($L2="","Pending",IF($L2-$B2<=IDPromptDays,"Y","Check"))) | O2: =IF($A2="","",IF(OR($K2<>"Y",$L2=""),0,IF($M2="",MAX(0,ReportDate-$L2),$M2-$L2))) -> 0 | P2: =IF($A2="","",IF($F2<>"Y","n/a",WORKDAY(EDATE($B2,1)+$O2-1,1,Holidays))) -> 46177 | Q2: =IF($A2="","",$B2+$O2+InternalDays) -> 46161 | R2: N | T2: =IF(OR($A2="",$R2<>"Y"),"",IF($S2="","Missing",IF(AND($F2="Y",$S2<=$P2),"Y","Late"))) | U2: =IF($A2="","",IF($F2<>"Y",$Q2,IF(AND($R2="Y",$T2="Y"),WORKDAY(EDATE($B2,3)+$O2-1,1,Holidays),$P2))) -> 46177 | V2: Privacy Analyst | W2: Closed | X2: N | Y2: 46160 | Z2: =IF($A2="","",IF($Y2<>"",$Y2-$B2,ReportDate-$B2)) -> 14 | AA2: =IF(OR($A2="",$W2="Closed"),"",$U2-ReportDate) | AB2: =IF($A2="","",IF($W2="Closed",IF($Y2<=$U2,"Closed on time","Closed late"),IF($W2="Awaiting ID","Paused",IF($AA2<0,"Overdue",IF($AA2<=RedDays,"Red",IF($AA2<=AmberDays,"Amber","Green")))))) -> Closed on time | AC2: =IF(OR($A2="",$Y2=""),"",IF($Y2<=$U2,"Y","N")) -> Y | AD2: N | AF2: =IF($A2="","",IF(IF(OR($B2="",$C2="",$D2="",$V2="",$W2=""),"missing required field; ","")&IF(COUNTIF($A$2:$A$201,$A2)>1,"duplicate ID; ","")&IF(AND($B2<>"",$B2>ReportDate),"received after snapshot date; ","")&IF(AND($I2<>"",$B2<>"",$I2<$B2),"acknowledged before receipt; ","")&IF(AND($K2="Y",$L2="",$W2<>"Logged"),"ID requested date missing; ","")&IF(AND($L2<>"",$M2<>"",$M2<$L2),"ID dates out of order; ","")&IF(AND($K2<>"Y",OR($L2<>"",$W2="Awaiting ID")),"ID fields used but ID_Check_Needed is not Y; ","")&IF(AND($R2="Y",$S2=""),"extension notice date missing; ","")&IF(AND($R2<>"Y",$S2<>""),"notice date but Extended is not Y; ","")&IF(AND($W2="Closed",$Y2=""),"closed without response date; ","")&IF(AND($Y2<>"",$W2<>"Closed"),"response date but status not Closed; ","")&IF(AND($Y2<>"",$B2<>"",$Y2<$B2),"response before receipt; ","")&IF(AND($AD2="Y",$AE2=""),"exemption needs a reason in Notes; ","")="","OK","Check: "&IF(OR($B2="",$C2="",$D2="",$V2="",$W2=""),"missing required field; ","")&IF(COUNTIF($A$2:$A$201,$A2)>1,"duplicate ID; ","")&IF(AND($B2<>"",$B2>ReportDate),"received after snapshot date; ","")&IF(AND($I2<>"",$B2<>"",$I2<$B2),"acknowledged before receipt; ","")&IF(AND($K2="Y",$L2="",$W2<>"Logged"),"ID requested date missing; ","")&IF(AND($L2<>"",$M2<>"",$M2<$L2),"ID dates out of order; ","")&IF(AND($K2<>"Y",OR($L2<>"",$W2="Awaiting ID")),"ID fields used but ID_Check_Needed is not Y; ","")&IF(AND($R2="Y",$S2=""),"extension notice date missing; ","")&IF(AND($R2<>"Y",$S2<>""),"notice date but Extended is not Y; ","")&IF(AND($W2="Closed",$Y2=""),"closed without response date; ","")&IF(AND($Y2<>"",$W2<>"Closed"),"response date but status not Closed; ","")&IF(AND($Y2<>"",$B2<>"",$Y2<$B2),"response before receipt; ","")&IF(AND($AD2="Y",$AE2=""),"exemption needs a reason in Notes; ",""))) -> OK
A3: DSR-2026-002 | B3: 46148 | C3: Web form | D3: Erasure | E3: =IF($A3="","",IFERROR(VLOOKUP($D3,ReqTypes,2,FALSE),"?")) -> Art 17 | F3: =IF($A3="","",IFERROR(VLOOKUP($D3,ReqTypes,3,FALSE),"?")) -> Y | G3: Customer | H3: Online | I3: 46149 | J3: =IF(OR($A3="",$I3=""),"",IF(NETWORKDAYS($B3,$I3,Holidays)-1<=AckDays,"Y","N")) -> Y | K3: N | N3: =IF(OR($A3="",$K3<>"Y"),"",IF($L3="","Pending",IF($L3-$B3<=IDPromptDays,"Y","Check"))) | O3: =IF($A3="","",IF(OR($K3<>"Y",$L3=""),0,IF($M3="",MAX(0,ReportDate-$L3),$M3-$L3))) -> 0 | P3: =IF($A3="","",IF($F3<>"Y","n/a",WORKDAY(EDATE($B3,1)+$O3-1,1,Holidays))) -> 46181 | Q3: =IF($A3="","",$B3+$O3+InternalDays) -> 46163 | R3: N | T3: =IF(OR($A3="",$R3<>"Y"),"",IF($S3="","Missing",IF(AND($F3="Y",$S3<=$P3),"Y","Late"))) | U3: =IF($A3="","",IF($F3<>"Y",$Q3,IF(AND($R3="Y",$T3="Y"),WORKDAY(EDATE($B3,3)+$O3-1,1,Holidays),$P3))) -> 46181 | V3: IT | W3: Closed | X3: N | Y3: 46154 | Z3: =IF($A3="","",IF($Y3<>"",$Y3-$B3,ReportDate-$B3)) -> 6 | AA3: =IF(OR($A3="",$W3="Closed"),"",$U3-ReportDate) | AB3: =IF($A3="","",IF($W3="Closed",IF($Y3<=$U3,"Closed on time","Closed late"),IF($W3="Awaiting ID","Paused",IF($AA3<0,"Overdue",IF($AA3<=RedDays,"Red",IF($AA3<=AmberDays,"Amber","Green")))))) -> Closed on time | AC3: =IF(OR($A3="",$Y3=""),"",IF($Y3<=$U3,"Y","N")) -> Y | AD3: N | AF3: =IF($A3="","",IF(IF(OR($B3="",$C3="",$D3="",$V3="",$W3=""),"missing required field; ","")&IF(COUNTIF($A$2:$A$201,$A3)>1,"duplicate ID; ","")&IF(AND($B3<>"",$B3>ReportDate),"received after snapshot date; ","")&IF(AND($I3<>"",$B3<>"",$I3<$B3),"acknowledged before receipt; ","")&IF(AND($K3="Y",$L3="",$W3<>"Logged"),"ID requested date missing; ","")&IF(AND($L3<>"",$M3<>"",$M3<$L3),"ID dates out of order; ","")&IF(AND($K3<>"Y",OR($L3<>"",$W3="Awaiting ID")),"ID fields used but ID_Check_Needed is not Y; ","")&IF(AND($R3="Y",$S3=""),"extension notice date missing; ","")&IF(AND($R3<>"Y",$S3<>""),"notice date but Extended is not Y; ","")&IF(AND($W3="Closed",$Y3=""),"closed without response date; ","")&IF(AND($Y3<>"",$W3<>"Closed"),"response date but status not Closed; ","")&IF(AND($Y3<>"",$B3<>"",$Y3<$B3),"response before receipt; ","")&IF(AND($AD3="Y",$AE3=""),"exemption needs a reason in Notes; ","")="","OK","Check: "&IF(OR($B3="",$C3="",$D3="",$V3="",$W3=""),"missing required field; ","")&IF(COUNTIF($A$2:$A$201,$A3)>1,"duplicate ID; ","")&IF(AND($B3<>"",$B3>ReportDate),"received after snapshot date; ","")&IF(AND($I3<>"",$B3<>"",$I3<$B3),"acknowledged before receipt; ","")&IF(AND($K3="Y",$L3="",$W3<>"Logged"),"ID requested date missing; ","")&IF(AND($L3<>"",$M3<>"",$M3<$L3),"ID dates out of order; ","")&IF(AND($K3<>"Y",OR($L3<>"",$W3="Awaiting ID")),"ID fields used but ID_Check_Needed is not Y; ","")&IF(AND($R3="Y",$S3=""),"extension notice date missing; ","")&IF(AND($R3<>"Y",$S3<>""),"notice date but Extended is not Y; ","")&IF(AND($W3="Closed",$Y3=""),"closed without response date; ","")&IF(AND($Y3<>"",$W3<>"Closed"),"response date but status not Closed; ","")&IF(AND($Y3<>"",$B3<>"",$Y3<$B3),"response before receipt; ","")&IF(AND($AD3="Y",$AE3=""),"exemption needs a reason in Notes; ",""))) -> OK
A4: DSR-2026-003 | B4: 46151 | C4: Privacy mailbox | D4: Objection - direct marketing | E4: =IF($A4="","",IFERROR(VLOOKUP($D4,ReqTypes,2,FALSE),"?")) -> Art 21(2) | F4: =IF($A4="","",IFERROR(VLOOKUP($D4,ReqTypes,3,FALSE),"?")) -> Y | G4: Customer | H4: Loyalty & Marketing | I4: 46153 | J4: =IF(OR($A4="",$I4=""),"",IF(NETWORKDAYS($B4,$I4,Holidays)-1<=AckDays,"Y","N")) -> Y | K4: N | N4: =IF(OR($A4="",$K4<>"Y"),"",IF($L4="","Pending",IF($L4-$B4<=IDPromptDays,"Y","Check"))) | O4: =IF($A4="","",IF(OR($K4<>"Y",$L4=""),0,IF($M4="",MAX(0,ReportDate-$L4),$M4-$L4))) -> 0 | P4: =IF($A4="","",IF($F4<>"Y","n/a",WORKDAY(EDATE($B4,1)+$O4-1,1,Holidays))) -> 46182 | Q4: =IF($A4="","",$B4+$O4+InternalDays) -> 46166 | R4: N | T4: =IF(OR($A4="",$R4<>"Y"),"",IF($S4="","Missing",IF(AND($F4="Y",$S4<=$P4),"Y","Late"))) | U4: =IF($A4="","",IF($F4<>"Y",$Q4,IF(AND($R4="Y",$T4="Y"),WORKDAY(EDATE($B4,3)+$O4-1,1,Holidays),$P4))) -> 46182 | V4: Marketing | W4: Closed | X4: N | Y4: 46154 | Z4: =IF($A4="","",IF($Y4<>"",$Y4-$B4,ReportDate-$B4)) -> 3 | AA4: =IF(OR($A4="",$W4="Closed"),"",$U4-ReportDate) | AB4: =IF($A4="","",IF($W4="Closed",IF($Y4<=$U4,"Closed on time","Closed late"),IF($W4="Awaiting ID","Paused",IF($AA4<0,"Overdue",IF($AA4<=RedDays,"Red",IF($AA4<=AmberDays,"Amber","Green")))))) -> Closed on time | AC4: =IF(OR($A4="",$Y4=""),"",IF($Y4<=$U4,"Y","N")) -> Y | AD4: N | AE4: Received on a Saturday | AF4: =IF($A4="","",IF(IF(OR($B4="",$C4="",$D4="",$V4="",$W4=""),"missing required field; ","")&IF(COUNTIF($A$2:$A$201,$A4)>1,"duplicate ID; ","")&IF(AND($B4<>"",$B4>ReportDate),"received after snapshot date; ","")&IF(AND($I4<>"",$B4<>"",$I4<$B4),"acknowledged before receipt; ","")&IF(AND($K4="Y",$L4="",$W4<>"Logged"),"ID requested date missing; ","")&IF(AND($L4<>"",$M4<>"",$M4<$L4),"ID dates out of order; ","")&IF(AND($K4<>"Y",OR($L4<>"",$W4="Awaiting ID")),"ID fields used but ID_Check_Needed is not Y; ","")&IF(AND($R4="Y",$S4=""),"extension notice date missing; ","")&IF(AND($R4<>"Y",$S4<>""),"notice date but Extended is not Y; ","")&IF(AND($W4="Closed",$Y4=""),"closed without response date; ","")&IF(AND($Y4<>"",$W4<>"Closed"),"response date but status not Closed; ","")&IF(AND($Y4<>"",$B4<>"",$Y4<$B4),"response before receipt; ","")&IF(AND($AD4="Y",$AE4=""),"exemption needs a reason in Notes; ","")="","OK","Check: "&IF(OR($B4="",$C4="",$D4="",$V4="",$W4=""),"missing required field; ","")&IF(COUNTIF($A$2:$A$201,$A4)>1,"duplicate ID; ","")&IF(AND($B4<>"",$B4>ReportDate),"received after snapshot date; ","")&IF(AND($I4<>"",$B4<>"",$I4<$B4),"acknowledged before receipt; ","")&IF(AND($K4="Y",$L4="",$W4<>"Logged"),"ID requested date missing; ","")&IF(AND($L4<>"",$M4<>"",$M4<$L4),"ID dates out of order; ","")&IF(AND($K4<>"Y",OR($L4<>"",$W4="Awaiting ID")),"ID fields used but ID_Check_Needed is not Y; ","")&IF(AND($R4="Y",$S4=""),"extension notice date missing; ","")&IF(AND($R4<>"Y",$S4<>""),"notice date but Extended is not Y; ","")&IF(AND($W4="Closed",$Y4=""),"closed without response date; ","")&IF(AND($Y4<>"",$W4<>"Closed"),"response date but status not Closed; ","")&IF(AND($Y4<>"",$B4<>"",$Y4<$B4),"response before receipt; ","")&IF(AND($AD4="Y",$AE4=""),"exemption needs a reason in Notes; ",""))) -> OK
A5: DSR-2026-004 | B5: 46154 | C5: Post | D5: Access | E5: =IF($A5="","",IFERROR(VLOOKUP($D5,ReqTypes,2,FALSE),"?")) -> Art 15 | F5: =IF($A5="","",IFERROR(VLOOKUP($D5,ReqTypes,3,FALSE),"?")) -> Y | G5: Former employee | H5: HR | I5: 46156 | J5: =IF(OR($A5="",$I5=""),"",IF(NETWORKDAYS($B5,$I5,Holidays)-1<=AckDays,"Y","N")) -> Y | K5: Y | L5: 46155 | M5: 46162 | N5: =IF(OR($A5="",$K5<>"Y"),"",IF($L5="","Pending",IF($L5-$B5<=IDPromptDays,"Y","Check"))) -> Y | O5: =IF($A5="","",IF(OR($K5<>"Y",$L5=""),0,IF($M5="",MAX(0,ReportDate-$L5),$M5-$L5))) -> 7 | P5: =IF($A5="","",IF($F5<>"Y","n/a",WORKDAY(EDATE($B5,1)+$O5-1,1,Holidays))) -> 46192 | Q5: =IF($A5="","",$B5+$O5+InternalDays) -> 46176 | R5: N | T5: =IF(OR($A5="",$R5<>"Y"),"",IF($S5="","Missing",IF(AND($F5="Y",$S5<=$P5),"Y","Late"))) | U5: =IF($A5="","",IF($F5<>"Y",$Q5,IF(AND($R5="Y",$T5="Y"),WORKDAY(EDATE($B5,3)+$O5-1,1,Holidays),$P5))) -> 46192 | V5: HR | W5: Closed | X5: N | Y5: 46181 | Z5: =IF($A5="","",IF($Y5<>"",$Y5-$B5,ReportDate-$B5)) -> 27 | AA5: =IF(OR($A5="",$W5="Closed"),"",$U5-ReportDate) | AB5: =IF($A5="","",IF($W5="Closed",IF($Y5<=$U5,"Closed on time","Closed late"),IF($W5="Awaiting ID","Paused",IF($AA5<0,"Overdue",IF($AA5<=RedDays,"Red",IF($AA5<=AmberDays,"Amber","Green")))))) -> Closed on time | AC5: =IF(OR($A5="",$Y5=""),"",IF($Y5<=$U5,"Y","N")) -> Y | AD5: N | AE5: ID requested by letter; clock paused until reply | AF5: =IF($A5="","",IF(IF(OR($B5="",$C5="",$D5="",$V5="",$W5=""),"missing required field; ","")&IF(COUNTIF($A$2:$A$201,$A5)>1,"duplicate ID; ","")&IF(AND($B5<>"",$B5>ReportDate),"received after snapshot date; ","")&IF(AND($I5<>"",$B5<>"",$I5<$B5),"acknowledged before receipt; ","")&IF(AND($K5="Y",$L5="",$W5<>"Logged"),"ID requested date missing; ","")&IF(AND($L5<>"",$M5<>"",$M5<$L5),"ID dates out of order; ","")&IF(AND($K5<>"Y",OR($L5<>"",$W5="Awaiting ID")),"ID fields used but ID_Check_Needed is not Y; ","")&IF(AND($R5="Y",$S5=""),"extension notice date missing; ","")&IF(AND($R5<>"Y",$S5<>""),"notice date but Extended is not Y; ","")&IF(AND($W5="Closed",$Y5=""),"closed without response date; ","")&IF(AND($Y5<>"",$W5<>"Closed"),"response date but status not Closed; ","")&IF(AND($Y5<>"",$B5<>"",$Y5<$B5),"response before receipt; ","")&IF(AND($AD5="Y",$AE5=""),"exemption needs a reason in Notes; ","")="","OK","Check: "&IF(OR($B5="",$C5="",$D5="",$V5="",$W5=""),"missing required field; ","")&IF(COUNTIF($A$2:$A$201,$A5)>1,"duplicate ID; ","")&IF(AND($B5<>"",$B5>ReportDate),"received after snapshot date; ","")&IF(AND($I5<>"",$B5<>"",$I5<$B5),"acknowledged before receipt; ","")&IF(AND($K5="Y",$L5="",$W5<>"Logged"),"ID requested date missing; ","")&IF(AND($L5<>"",$M5<>"",$M5<$L5),"ID dates out of order; ","")&IF(AND($K5<>"Y",OR($L5<>"",$W5="Awaiting ID")),"ID fields used but ID_Check_Needed is not Y; ","")&IF(AND($R5="Y",$S5=""),"extension notice date missing; ","")&IF(AND($R5<>"Y",$S5<>""),"notice date but Extended is not Y; ","")&IF(AND($W5="Closed",$Y5=""),"closed without response date; ","")&IF(AND($Y5<>"",$W5<>"Closed"),"response date but status not Closed; ","")&IF(AND($Y5<>"",$B5<>"",$Y5<$B5),"response before receipt; ","")&IF(AND($AD5="Y",$AE5=""),"exemption needs a reason in Notes; ",""))) -> OK
A6: DSR-2026-005 | B6: 46157 | C6: In-store | D6: Access | E6: =IF($A6="","",IFERROR(VLOOKUP($D6,ReqTypes,2,FALSE),"?")) -> Art 15 | F6: =IF($A6="","",IFERROR(VLOOKUP($D6,ReqTypes,3,FALSE),"?")) -> Y | G6: Customer | H6: CCTV & Security | I6: 46160 | J6: =IF(OR($A6="",$I6=""),"",IF(NETWORKDAYS($B6,$I6,Holidays)-1<=AckDays,"Y","N")) -> Y | K6: Y | L6: 46157 | M6: 46160 | N6: =IF(OR($A6="",$K6<>"Y"),"",IF($L6="","Pending",IF($L6-$B6<=IDPromptDays,"Y","Check"))) -> Y | O6: =IF($A6="","",IF(OR($K6<>"Y",$L6=""),0,IF($M6="",MAX(0,ReportDate-$L6),$M6-$L6))) -> 3 | P6: =IF($A6="","",IF($F6<>"Y","n/a",WORKDAY(EDATE($B6,1)+$O6-1,1,Holidays))) -> 46191 | Q6: =IF($A6="","",$B6+$O6+InternalDays) -> 46175 | R6: N | T6: =IF(OR($A6="",$R6<>"Y"),"",IF($S6="","Missing",IF(AND($F6="Y",$S6<=$P6),"Y","Late"))) | U6: =IF($A6="","",IF($F6<>"Y",$Q6,IF(AND($R6="Y",$T6="Y"),WORKDAY(EDATE($B6,3)+$O6-1,1,Holidays),$P6))) -> 46191 | V6: Privacy Analyst | W6: Closed | X6: N | Y6: 46176 | Z6: =IF($A6="","",IF($Y6<>"",$Y6-$B6,ReportDate-$B6)) -> 19 | AA6: =IF(OR($A6="",$W6="Closed"),"",$U6-ReportDate) | AB6: =IF($A6="","",IF($W6="Closed",IF($Y6<=$U6,"Closed on time","Closed late"),IF($W6="Awaiting ID","Paused",IF($AA6<0,"Overdue",IF($AA6<=RedDays,"Red",IF($AA6<=AmberDays,"Amber","Green")))))) -> Closed on time | AC6: =IF(OR($A6="",$Y6=""),"",IF($Y6<=$U6,"Y","N")) -> Y | AD6: Y | AE6: CCTV footage: 2 other shoppers blurred. Redaction schedule RS-005 (Art 15(4)) | AF6: =IF($A6="","",IF(IF(OR($B6="",$C6="",$D6="",$V6="",$W6=""),"missing required field; ","")&IF(COUNTIF($A$2:$A$201,$A6)>1,"duplicate ID; ","")&IF(AND($B6<>"",$B6>ReportDate),"received after snapshot date; ","")&IF(AND($I6<>"",$B6<>"",$I6<$B6),"acknowledged before receipt; ","")&IF(AND($K6="Y",$L6="",$W6<>"Logged"),"ID requested date missing; ","")&IF(AND($L6<>"",$M6<>"",$M6<$L6),"ID dates out of order; ","")&IF(AND($K6<>"Y",OR($L6<>"",$W6="Awaiting ID")),"ID fields used but ID_Check_Needed is not Y; ","")&IF(AND($R6="Y",$S6=""),"extension notice date missing; ","")&IF(AND($R6<>"Y",$S6<>""),"notice date but Extended is not Y; ","")&IF(AND($W6="Closed",$Y6=""),"closed without response date; ","")&IF(AND($Y6<>"",$W6<>"Closed"),"response date but status not Closed; ","")&IF(AND($Y6<>"",$B6<>"",$Y6<$B6),"response before receipt; ","")&IF(AND($AD6="Y",$AE6=""),"exemption needs a reason in Notes; ","")="","OK","Check: "&IF(OR($B6="",$C6="",$D6="",$V6="",$W6=""),"missing required field; ","")&IF(COUNTIF($A$2:$A$201,$A6)>1,"duplicate ID; ","")&IF(AND($B6<>"",$B6>ReportDate),"received after snapshot date; ","")&IF(AND($I6<>"",$B6<>"",$I6<$B6),"acknowledged before receipt; ","")&IF(AND($K6="Y",$L6="",$W6<>"Logged"),"ID requested date missing; ","")&IF(AND($L6<>"",$M6<>"",$M6<$L6),"ID dates out of order; ","")&IF(AND($K6<>"Y",OR($L6<>"",$W6="Awaiting ID")),"ID fields used but ID_Check_Needed is not Y; ","")&IF(AND($R6="Y",$S6=""),"extension notice date missing; ","")&IF(AND($R6<>"Y",$S6<>""),"notice date but Extended is not Y; ","")&IF(AND($W6="Closed",$Y6=""),"closed without response date; ","")&IF(AND($Y6<>"",$W6<>"Closed"),"response date but status not Closed; ","")&IF(AND($Y6<>"",$B6<>"",$Y6<$B6),"response before receipt; ","")&IF(AND($AD6="Y",$AE6=""),"exemption needs a reason in Notes; ",""))) -> OK
A7: DSR-2026-006 | B7: 46162 | C7: Privacy mailbox | D7: Rectification | E7: =IF($A7="","",IFERROR(VLOOKUP($D7,ReqTypes,2,FALSE),"?")) -> Art 16 | F7: =IF($A7="","",IFERROR(VLOOKUP($D7,ReqTypes,3,FALSE),"?")) -> Y | G7: Customer | H7: Loyalty & Marketing | I7: 46163 | J7: =IF(OR($A7="",$I7=""),"",IF(NETWORKDAYS($B7,$I7,Holidays)-1<=AckDays,"Y","N")) -> Y | K7: N | N7: =IF(OR($A7="",$K7<>"Y"),"",IF($L7="","Pending",IF($L7-$B7<=IDPromptDays,"Y","Check"))) | O7: =IF($A7="","",IF(OR($K7<>"Y",$L7=""),0,IF($M7="",MAX(0,ReportDate-$L7),$M7-$L7))) -> 0 | P7: =IF($A7="","",IF($F7<>"Y","n/a",WORKDAY(EDATE($B7,1)+$O7-1,1,Holidays))) -> 46195 | Q7: =IF($A7="","",$B7+$O7+InternalDays) -> 46177 | R7: N | T7: =IF(OR($A7="",$R7<>"Y"),"",IF($S7="","Missing",IF(AND($F7="Y",$S7<=$P7),"Y","Late"))) | U7: =IF($A7="","",IF($F7<>"Y",$Q7,IF(AND($R7="Y",$T7="Y"),WORKDAY(EDATE($B7,3)+$O7-1,1,Holidays),$P7))) -> 46195 | V7: Privacy Analyst | W7: Closed | X7: N | Y7: 46167 | Z7: =IF($A7="","",IF($Y7<>"",$Y7-$B7,ReportDate-$B7)) -> 5 | AA7: =IF(OR($A7="",$W7="Closed"),"",$U7-ReportDate) | AB7: =IF($A7="","",IF($W7="Closed",IF($Y7<=$U7,"Closed on time","Closed late"),IF($W7="Awaiting ID","Paused",IF($AA7<0,"Overdue",IF($AA7<=RedDays,"Red",IF($AA7<=AmberDays,"Amber","Green")))))) -> Closed on time | AC7: =IF(OR($A7="",$Y7=""),"",IF($Y7<=$U7,"Y","N")) -> Y | AD7: N | AF7: =IF($A7="","",IF(IF(OR($B7="",$C7="",$D7="",$V7="",$W7=""),"missing required field; ","")&IF(COUNTIF($A$2:$A$201,$A7)>1,"duplicate ID; ","")&IF(AND($B7<>"",$B7>ReportDate),"received after snapshot date; ","")&IF(AND($I7<>"",$B7<>"",$I7<$B7),"acknowledged before receipt; ","")&IF(AND($K7="Y",$L7="",$W7<>"Logged"),"ID requested date missing; ","")&IF(AND($L7<>"",$M7<>"",$M7<$L7),"ID dates out of order; ","")&IF(AND($K7<>"Y",OR($L7<>"",$W7="Awaiting ID")),"ID fields used but ID_Check_Needed is not Y; ","")&IF(AND($R7="Y",$S7=""),"extension notice date missing; ","")&IF(AND($R7<>"Y",$S7<>""),"notice date but Extended is not Y; ","")&IF(AND($W7="Closed",$Y7=""),"closed without response date; ","")&IF(AND($Y7<>"",$W7<>"Closed"),"response date but status not Closed; ","")&IF(AND($Y7<>"",$B7<>"",$Y7<$B7),"response before receipt; ","")&IF(AND($AD7="Y",$AE7=""),"exemption needs a reason in Notes; ","")="","OK","Check: "&IF(OR($B7="",$C7="",$D7="",$V7="",$W7=""),"missing required field; ","")&IF(COUNTIF($A$2:$A$201,$A7)>1,"duplicate ID; ","")&IF(AND($B7<>"",$B7>ReportDate),"received after snapshot date; ","")&IF(AND($I7<>"",$B7<>"",$I7<$B7),"acknowledged before receipt; ","")&IF(AND($K7="Y",$L7="",$W7<>"Logged"),"ID requested date missing; ","")&IF(AND($L7<>"",$M7<>"",$M7<$L7),"ID dates out of order; ","")&IF(AND($K7<>"Y",OR($L7<>"",$W7="Awaiting ID")),"ID fields used but ID_Check_Needed is not Y; ","")&IF(AND($R7="Y",$S7=""),"extension notice date missing; ","")&IF(AND($R7<>"Y",$S7<>""),"notice date but Extended is not Y; ","")&IF(AND($W7="Closed",$Y7=""),"closed without response date; ","")&IF(AND($Y7<>"",$W7<>"Closed"),"response date but status not Closed; ","")&IF(AND($Y7<>"",$B7<>"",$Y7<$B7),"response before receipt; ","")&IF(AND($AD7="Y",$AE7=""),"exemption needs a reason in Notes; ",""))) -> OK
A8: DSR-2026-007 | B8: 46167 | C8: Customer service | D8: General query | E8: =IF($A8="","",IFERROR(VLOOKUP($D8,ReqTypes,2,FALSE),"?")) -> n/a | F8: =IF($A8="","",IFERROR(VLOOKUP($D8,ReqTypes,3,FALSE),"?")) -> N | G8: Customer | H8: Customer Service | I8: 46168 | J8: =IF(OR($A8="",$I8=""),"",IF(NETWORKDAYS($B8,$I8,Holidays)-1<=AckDays,"Y","N")) -> Y | K8: N | N8: =IF(OR($A8="",$K8<>"Y"),"",IF($L8="","Pending",IF($L8-$B8<=IDPromptDays,"Y","Check"))) | O8: =IF($A8="","",IF(OR($K8<>"Y",$L8=""),0,IF($M8="",MAX(0,ReportDate-$L8),$M8-$L8))) -> 0 | P8: =IF($A8="","",IF($F8<>"Y","n/a",WORKDAY(EDATE($B8,1)+$O8-1,1,Holidays))) -> n/a | Q8: =IF($A8="","",$B8+$O8+InternalDays) -> 46182 | R8: N | T8: =IF(OR($A8="",$R8<>"Y"),"",IF($S8="","Missing",IF(AND($F8="Y",$S8<=$P8),"Y","Late"))) | U8: =IF($A8="","",IF($F8<>"Y",$Q8,IF(AND($R8="Y",$T8="Y"),WORKDAY(EDATE($B8,3)+$O8-1,1,Holidays),$P8))) -> 46182 | V8: Privacy Analyst | W8: Closed | X8: N | Y8: 46174 | Z8: =IF($A8="","",IF($Y8<>"",$Y8-$B8,ReportDate-$B8)) -> 7 | AA8: =IF(OR($A8="",$W8="Closed"),"",$U8-ReportDate) | AB8: =IF($A8="","",IF($W8="Closed",IF($Y8<=$U8,"Closed on time","Closed late"),IF($W8="Awaiting ID","Paused",IF($AA8<0,"Overdue",IF($AA8<=RedDays,"Red",IF($AA8<=AmberDays,"Amber","Green")))))) -> Closed on time | AC8: =IF(OR($A8="",$Y8=""),"",IF($Y8<=$U8,"Y","N")) -> Y | AD8: N | AE8: Not a statutory request: internal target only | AF8: =IF($A8="","",IF(IF(OR($B8="",$C8="",$D8="",$V8="",$W8=""),"missing required field; ","")&IF(COUNTIF($A$2:$A$201,$A8)>1,"duplicate ID; ","")&IF(AND($B8<>"",$B8>ReportDate),"received after snapshot date; ","")&IF(AND($I8<>"",$B8<>"",$I8<$B8),"acknowledged before receipt; ","")&IF(AND($K8="Y",$L8="",$W8<>"Logged"),"ID requested date missing; ","")&IF(AND($L8<>"",$M8<>"",$M8<$L8),"ID dates out of order; ","")&IF(AND($K8<>"Y",OR($L8<>"",$W8="Awaiting ID")),"ID fields used but ID_Check_Needed is not Y; ","")&IF(AND($R8="Y",$S8=""),"extension notice date missing; ","")&IF(AND($R8<>"Y",$S8<>""),"notice date but Extended is not Y; ","")&IF(AND($W8="Closed",$Y8=""),"closed without response date; ","")&IF(AND($Y8<>"",$W8<>"Closed"),"response date but status not Closed; ","")&IF(AND($Y8<>"",$B8<>"",$Y8<$B8),"response before receipt; ","")&IF(AND($AD8="Y",$AE8=""),"exemption needs a reason in Notes; ","")="","OK","Check: "&IF(OR($B8="",$C8="",$D8="",$V8="",$W8=""),"missing required field; ","")&IF(COUNTIF($A$2:$A$201,$A8)>1,"duplicate ID; ","")&IF(AND($B8<>"",$B8>ReportDate),"received after snapshot date; ","")&IF(AND($I8<>"",$B8<>"",$I8<$B8),"acknowledged before receipt; ","")&IF(AND($K8="Y",$L8="",$W8<>"Logged"),"ID requested date missing; ","")&IF(AND($L8<>"",$M8<>"",$M8<$L8),"ID dates out of order; ","")&IF(AND($K8<>"Y",OR($L8<>"",$W8="Awaiting ID")),"ID fields used but ID_Check_Needed is not Y; ","")&IF(AND($R8="Y",$S8=""),"extension notice date missing; ","")&IF(AND($R8<>"Y",$S8<>""),"notice date but Extended is not Y; ","")&IF(AND($W8="Closed",$Y8=""),"closed without response date; ","")&IF(AND($Y8<>"",$W8<>"Closed"),"response date but status not Closed; ","")&IF(AND($Y8<>"",$B8<>"",$Y8<$B8),"response before receipt; ","")&IF(AND($AD8="Y",$AE8=""),"exemption needs a reason in Notes; ",""))) -> OK
A9: DSR-2026-008 | B9: 46170 | C9: Privacy mailbox | D9: Access | E9: =IF($A9="","",IFERROR(VLOOKUP($D9,ReqTypes,2,FALSE),"?")) -> Art 15 | F9: =IF($A9="","",IFERROR(VLOOKUP($D9,ReqTypes,3,FALSE),"?")) -> Y | G9: Employee | H9: HR | I9: 46171 | J9: =IF(OR($A9="",$I9=""),"",IF(NETWORKDAYS($B9,$I9,Holidays)-1<=AckDays,"Y","N")) -> Y | K9: N | N9: =IF(OR($A9="",$K9<>"Y"),"",IF($L9="","Pending",IF($L9-$B9<=IDPromptDays,"Y","Check"))) | O9: =IF($A9="","",IF(OR($K9<>"Y",$L9=""),0,IF($M9="",MAX(0,ReportDate-$L9),$M9-$L9))) -> 0 | P9: =IF($A9="","",IF($F9<>"Y","n/a",WORKDAY(EDATE($B9,1)+$O9-1,1,Holidays))) -> 46202 | Q9: =IF($A9="","",$B9+$O9+InternalDays) -> 46185 | R9: N | T9: =IF(OR($A9="",$R9<>"Y"),"",IF($S9="","Missing",IF(AND($F9="Y",$S9<=$P9),"Y","Late"))) | U9: =IF($A9="","",IF($F9<>"Y",$Q9,IF(AND($R9="Y",$T9="Y"),WORKDAY(EDATE($B9,3)+$O9-1,1,Holidays),$P9))) -> 46202 | V9: HR | W9: Closed | X9: N | Y9: 46191 | Z9: =IF($A9="","",IF($Y9<>"",$Y9-$B9,ReportDate-$B9)) -> 21 | AA9: =IF(OR($A9="",$W9="Closed"),"",$U9-ReportDate) | AB9: =IF($A9="","",IF($W9="Closed",IF($Y9<=$U9,"Closed on time","Closed late"),IF($W9="Awaiting ID","Paused",IF($AA9<0,"Overdue",IF($AA9<=RedDays,"Red",IF($AA9<=AmberDays,"Amber","Green")))))) -> Closed on time | AC9: =IF(OR($A9="",$Y9=""),"",IF($Y9<=$U9,"Y","N")) -> Y | AD9: N | AF9: =IF($A9="","",IF(IF(OR($B9="",$C9="",$D9="",$V9="",$W9=""),"missing required field; ","")&IF(COUNTIF($A$2:$A$201,$A9)>1,"duplicate ID; ","")&IF(AND($B9<>"",$B9>ReportDate),"received after snapshot date; ","")&IF(AND($I9<>"",$B9<>"",$I9<$B9),"acknowledged before receipt; ","")&IF(AND($K9="Y",$L9="",$W9<>"Logged"),"ID requested date missing; ","")&IF(AND($L9<>"",$M9<>"",$M9<$L9),"ID dates out of order; ","")&IF(AND($K9<>"Y",OR($L9<>"",$W9="Awaiting ID")),"ID fields used but ID_Check_Needed is not Y; ","")&IF(AND($R9="Y",$S9=""),"extension notice date missing; ","")&IF(AND($R9<>"Y",$S9<>""),"notice date but Extended is not Y; ","")&IF(AND($W9="Closed",$Y9=""),"closed without response date; ","")&IF(AND($Y9<>"",$W9<>"Closed"),"response date but status not Closed; ","")&IF(AND($Y9<>"",$B9<>"",$Y9<$B9),"response before receipt; ","")&IF(AND($AD9="Y",$AE9=""),"exemption needs a reason in Notes; ","")="","OK","Check: "&IF(OR($B9="",$C9="",$D9="",$V9="",$W9=""),"missing required field; ","")&IF(COUNTIF($A$2:$A$201,$A9)>1,"duplicate ID; ","")&IF(AND($B9<>"",$B9>ReportDate),"received after snapshot date; ","")&IF(AND($I9<>"",$B9<>"",$I9<$B9),"acknowledged before receipt; ","")&IF(AND($K9="Y",$L9="",$W9<>"Logged"),"ID requested date missing; ","")&IF(AND($L9<>"",$M9<>"",$M9<$L9),"ID dates out of order; ","")&IF(AND($K9<>"Y",OR($L9<>"",$W9="Awaiting ID")),"ID fields used but ID_Check_Needed is not Y; ","")&IF(AND($R9="Y",$S9=""),"extension notice date missing; ","")&IF(AND($R9<>"Y",$S9<>""),"notice date but Extended is not Y; ","")&IF(AND($W9="Closed",$Y9=""),"closed without response date; ","")&IF(AND($Y9<>"",$W9<>"Closed"),"response date but status not Closed; ","")&IF(AND($Y9<>"",$B9<>"",$Y9<$B9),"response before receipt; ","")&IF(AND($AD9="Y",$AE9=""),"exemption needs a reason in Notes; ",""))) -> OK
A10: DSR-2026-009 | B10: 46175 | C10: Web form | D10: Erasure | E10: =IF($A10="","",IFERROR(VLOOKUP($D10,ReqTypes,2,FALSE),"?")) -> Art 17 | F10: =IF($A10="","",IFERROR(VLOOKUP($D10,ReqTypes,3,FALSE),"?")) -> Y | G10: Customer | H10: Online | I10: 46176 | J10: =IF(OR($A10="",$I10=""),"",IF(NETWORKDAYS($B10,$I10,Holidays)-1<=AckDays,"Y","N")) -> Y | K10: N | N10: =IF(OR($A10="",$K10<>"Y"),"",IF($L10="","Pending",IF($L10-$B10<=IDPromptDays,"Y","Check"))) | O10: =IF($A10="","",IF(OR($K10<>"Y",$L10=""),0,IF($M10="",MAX(0,ReportDate-$L10),$M10-$L10))) -> 0 | P10: =IF($A10="","",IF($F10<>"Y","n/a",WORKDAY(EDATE($B10,1)+$O10-1,1,Holidays))) -> 46205 | Q10: =IF($A10="","",$B10+$O10+InternalDays) -> 46190 | R10: N | T10: =IF(OR($A10="",$R10<>"Y"),"",IF($S10="","Missing",IF(AND($F10="Y",$S10<=$P10),"Y","Late"))) | U10: =IF($A10="","",IF($F10<>"Y",$Q10,IF(AND($R10="Y",$T10="Y"),WORKDAY(EDATE($B10,3)+$O10-1,1,Holidays),$P10))) -> 46205 | V10: IT | W10: Closed | X10: N | Y10: 46184 | Z10: =IF($A10="","",IF($Y10<>"",$Y10-$B10,ReportDate-$B10)) -> 9 | AA10: =IF(OR($A10="",$W10="Closed"),"",$U10-ReportDate) | AB10: =IF($A10="","",IF($W10="Closed",IF($Y10<=$U10,"Closed on time","Closed late"),IF($W10="Awaiting ID","Paused",IF($AA10<0,"Overdue",IF($AA10<=RedDays,"Red",IF($AA10<=AmberDays,"Amber","Green")))))) -> Closed on time | AC10: =IF(OR($A10="",$Y10=""),"",IF($Y10<=$U10,"Y","N")) -> Y | AD10: N | AF10: =IF($A10="","",IF(IF(OR($B10="",$C10="",$D10="",$V10="",$W10=""),"missing required field; ","")&IF(COUNTIF($A$2:$A$201,$A10)>1,"duplicate ID; ","")&IF(AND($B10<>"",$B10>ReportDate),"received after snapshot date; ","")&IF(AND($I10<>"",$B10<>"",$I10<$B10),"acknowledged before receipt; ","")&IF(AND($K10="Y",$L10="",$W10<>"Logged"),"ID requested date missing; ","")&IF(AND($L10<>"",$M10<>"",$M10<$L10),"ID dates out of order; ","")&IF(AND($K10<>"Y",OR($L10<>"",$W10="Awaiting ID")),"ID fields used but ID_Check_Needed is not Y; ","")&IF(AND($R10="Y",$S10=""),"extension notice date missing; ","")&IF(AND($R10<>"Y",$S10<>""),"notice date but Extended is not Y; ","")&IF(AND($W10="Closed",$Y10=""),"closed without response date; ","")&IF(AND($Y10<>"",$W10<>"Closed"),"response date but status not Closed; ","")&IF(AND($Y10<>"",$B10<>"",$Y10<$B10),"response before receipt; ","")&IF(AND($AD10="Y",$AE10=""),"exemption needs a reason in Notes; ","")="","OK","Check: "&IF(OR($B10="",$C10="",$D10="",$V10="",$W10=""),"missing required field; ","")&IF(COUNTIF($A$2:$A$201,$A10)>1,"duplicate ID; ","")&IF(AND($B10<>"",$B10>ReportDate),"received after snapshot date; ","")&IF(AND($I10<>"",$B10<>"",$I10<$B10),"acknowledged before receipt; ","")&IF(AND($K10="Y",$L10="",$W10<>"Logged"),"ID requested date missing; ","")&IF(AND($L10<>"",$M10<>"",$M10<$L10),"ID dates out of order; ","")&IF(AND($K10<>"Y",OR($L10<>"",$W10="Awaiting ID")),"ID fields used but ID_Check_Needed is not Y; ","")&IF(AND($R10="Y",$S10=""),"extension notice date missing; ","")&IF(AND($R10<>"Y",$S10<>""),"notice date but Extended is not Y; ","")&IF(AND($W10="Closed",$Y10=""),"closed without response date; ","")&IF(AND($Y10<>"",$W10<>"Closed"),"response date but status not Closed; ","")&IF(AND($Y10<>"",$B10<>"",$Y10<$B10),"response before receipt; ","")&IF(AND($AD10="Y",$AE10=""),"exemption needs a reason in Notes; ",""))) -> OK
A11: DSR-2026-010 | B11: 46178 | C11: Privacy mailbox | D11: Objection - direct marketing | E11: =IF($A11="","",IFERROR(VLOOKUP($D11,ReqTypes,2,FALSE),"?")) -> Art 21(2) | F11: =IF($A11="","",IFERROR(VLOOKUP($D11,ReqTypes,3,FALSE),"?")) -> Y | G11: Customer | H11: Loyalty & Marketing | I11: 46183 | J11: =IF(OR($A11="",$I11=""),"",IF(NETWORKDAYS($B11,$I11,Holidays)-1<=AckDays,"Y","N")) -> N | K11: N | N11: =IF(OR($A11="",$K11<>"Y"),"",IF($L11="","Pending",IF($L11-$B11<=IDPromptDays,"Y","Check"))) | O11: =IF($A11="","",IF(OR($K11<>"Y",$L11=""),0,IF($M11="",MAX(0,ReportDate-$L11),$M11-$L11))) -> 0 | P11: =IF($A11="","",IF($F11<>"Y","n/a",WORKDAY(EDATE($B11,1)+$O11-1,1,Holidays))) -> 46209 | Q11: =IF($A11="","",$B11+$O11+InternalDays) -> 46193 | R11: N | T11: =IF(OR($A11="",$R11<>"Y"),"",IF($S11="","Missing",IF(AND($F11="Y",$S11<=$P11),"Y","Late"))) | U11: =IF($A11="","",IF($F11<>"Y",$Q11,IF(AND($R11="Y",$T11="Y"),WORKDAY(EDATE($B11,3)+$O11-1,1,Holidays),$P11))) -> 46209 | V11: Marketing | W11: Closed | X11: N | Y11: 46184 | Z11: =IF($A11="","",IF($Y11<>"",$Y11-$B11,ReportDate-$B11)) -> 6 | AA11: =IF(OR($A11="",$W11="Closed"),"",$U11-ReportDate) | AB11: =IF($A11="","",IF($W11="Closed",IF($Y11<=$U11,"Closed on time","Closed late"),IF($W11="Awaiting ID","Paused",IF($AA11<0,"Overdue",IF($AA11<=RedDays,"Red",IF($AA11<=AmberDays,"Amber","Green")))))) -> Closed on time | AC11: =IF(OR($A11="",$Y11=""),"",IF($Y11<=$U11,"Y","N")) -> Y | AD11: N | AE11: Acknowledgement missed the internal 2-working-day target | AF11: =IF($A11="","",IF(IF(OR($B11="",$C11="",$D11="",$V11="",$W11=""),"missing required field; ","")&IF(COUNTIF($A$2:$A$201,$A11)>1,"duplicate ID; ","")&IF(AND($B11<>"",$B11>ReportDate),"received after snapshot date; ","")&IF(AND($I11<>"",$B11<>"",$I11<$B11),"acknowledged before receipt; ","")&IF(AND($K11="Y",$L11="",$W11<>"Logged"),"ID requested date missing; ","")&IF(AND($L11<>"",$M11<>"",$M11<$L11),"ID dates out of order; ","")&IF(AND($K11<>"Y",OR($L11<>"",$W11="Awaiting ID")),"ID fields used but ID_Check_Needed is not Y; ","")&IF(AND($R11="Y",$S11=""),"extension notice date missing; ","")&IF(AND($R11<>"Y",$S11<>""),"notice date but Extended is not Y; ","")&IF(AND($W11="Closed",$Y11=""),"closed without response date; ","")&IF(AND($Y11<>"",$W11<>"Closed"),"response date but status not Closed; ","")&IF(AND($Y11<>"",$B11<>"",$Y11<$B11),"response before receipt; ","")&IF(AND($AD11="Y",$AE11=""),"exemption needs a reason in Notes; ","")="","OK","Check: "&IF(OR($B11="",$C11="",$D11="",$V11="",$W11=""),"missing required field; ","")&IF(COUNTIF($A$2:$A$201,$A11)>1,"duplicate ID; ","")&IF(AND($B11<>"",$B11>ReportDate),"received after snapshot date; ","")&IF(AND($I11<>"",$B11<>"",$I11<$B11),"acknowledged before receipt; ","")&IF(AND($K11="Y",$L11="",$W11<>"Logged"),"ID requested date missing; ","")&IF(AND($L11<>"",$M11<>"",$M11<$L11),"ID dates out of order; ","")&IF(AND($K11<>"Y",OR($L11<>"",$W11="Awaiting ID")),"ID fields used but ID_Check_Needed is not Y; ","")&IF(AND($R11="Y",$S11=""),"extension notice date missing; ","")&IF(AND($R11<>"Y",$S11<>""),"notice date but Extended is not Y; ","")&IF(AND($W11="Closed",$Y11=""),"closed without response date; ","")&IF(AND($Y11<>"",$W11<>"Closed"),"response date but status not Closed; ","")&IF(AND($Y11<>"",$B11<>"",$Y11<$B11),"response before receipt; ","")&IF(AND($AD11="Y",$AE11=""),"exemption needs a reason in Notes; ",""))) -> OK
A12: DSR-2026-011 | B12: 46183 | C12: Post | D12: Access | E12: =IF($A12="","",IFERROR(VLOOKUP($D12,ReqTypes,2,FALSE),"?")) -> Art 15 | F12: =IF($A12="","",IFERROR(VLOOKUP($D12,ReqTypes,3,FALSE),"?")) -> Y | G12: Customer | H12: Stores | I12: 46185 | J12: =IF(OR($A12="",$I12=""),"",IF(NETWORKDAYS($B12,$I12,Holidays)-1<=AckDays,"Y","N")) -> Y | K12: Y | L12: 46189 | M12: 46195 | N12: =IF(OR($A12="",$K12<>"Y"),"",IF($L12="","Pending",IF($L12-$B12<=IDPromptDays,"Y","Check"))) -> Check | O12: =IF($A12="","",IF(OR($K12<>"Y",$L12=""),0,IF($M12="",MAX(0,ReportDate-$L12),$M12-$L12))) -> 6 | P12: =IF($A12="","",IF($F12<>"Y","n/a",WORKDAY(EDATE($B12,1)+$O12-1,1,Holidays))) -> 46219 | Q12: =IF($A12="","",$B12+$O12+InternalDays) -> 46204 | R12: N | T12: =IF(OR($A12="",$R12<>"Y"),"",IF($S12="","Missing",IF(AND($F12="Y",$S12<=$P12),"Y","Late"))) | U12: =IF($A12="","",IF($F12<>"Y",$Q12,IF(AND($R12="Y",$T12="Y"),WORKDAY(EDATE($B12,3)+$O12-1,1,Holidays),$P12))) -> 46219 | V12: Privacy Analyst | W12: Closed | X12: N | Y12: 46216 | Z12: =IF($A12="","",IF($Y12<>"",$Y12-$B12,ReportDate-$B12)) -> 33 | AA12: =IF(OR($A12="",$W12="Closed"),"",$U12-ReportDate) | AB12: =IF($A12="","",IF($W12="Closed",IF($Y12<=$U12,"Closed on time","Closed late"),IF($W12="Awaiting ID","Paused",IF($AA12<0,"Overdue",IF($AA12<=RedDays,"Red",IF($AA12<=AmberDays,"Amber","Green")))))) -> Closed on time | AC12: =IF(OR($A12="",$Y12=""),"",IF($Y12<=$U12,"Y","N")) -> Y | AD12: N | AE12: ID requested 6 days after receipt: pause may not be defensible. Reviewed by Privacy Manager | AF12: =IF($A12="","",IF(IF(OR($B12="",$C12="",$D12="",$V12="",$W12=""),"missing required field; ","")&IF(COUNTIF($A$2:$A$201,$A12)>1,"duplicate ID; ","")&IF(AND($B12<>"",$B12>ReportDate),"received after snapshot date; ","")&IF(AND($I12<>"",$B12<>"",$I12<$B12),"acknowledged before receipt; ","")&IF(AND($K12="Y",$L12="",$W12<>"Logged"),"ID requested date missing; ","")&IF(AND($L12<>"",$M12<>"",$M12<$L12),"ID dates out of order; ","")&IF(AND($K12<>"Y",OR($L12<>"",$W12="Awaiting ID")),"ID fields used but ID_Check_Needed is not Y; ","")&IF(AND($R12="Y",$S12=""),"extension notice date missing; ","")&IF(AND($R12<>"Y",$S12<>""),"notice date but Extended is not Y; ","")&IF(AND($W12="Closed",$Y12=""),"closed without response date; ","")&IF(AND($Y12<>"",$W12<>"Closed"),"response date but status not Closed; ","")&IF(AND($Y12<>"",$B12<>"",$Y12<$B12),"response before receipt; ","")&IF(AND($AD12="Y",$AE12=""),"exemption needs a reason in Notes; ","")="","OK","Check: "&IF(OR($B12="",$C12="",$D12="",$V12="",$W12=""),"missing required field; ","")&IF(COUNTIF($A$2:$A$201,$A12)>1,"duplicate ID; ","")&IF(AND($B12<>"",$B12>ReportDate),"received after snapshot date; ","")&IF(AND($I12<>"",$B12<>"",$I12<$B12),"acknowledged before receipt; ","")&IF(AND($K12="Y",$L12="",$W12<>"Logged"),"ID requested date missing; ","")&IF(AND($L12<>"",$M12<>"",$M12<$L12),"ID dates out of order; ","")&IF(AND($K12<>"Y",OR($L12<>"",$W12="Awaiting ID")),"ID fields used but ID_Check_Needed is not Y; ","")&IF(AND($R12="Y",$S12=""),"extension notice date missing; ","")&IF(AND($R12<>"Y",$S12<>""),"notice date but Extended is not Y; ","")&IF(AND($W12="Closed",$Y12=""),"closed without response date; ","")&IF(AND($Y12<>"",$W12<>"Closed"),"response date but status not Closed; ","")&IF(AND($Y12<>"",$B12<>"",$Y12<$B12),"response before receipt; ","")&IF(AND($AD12="Y",$AE12=""),"exemption needs a reason in Notes; ",""))) -> OK
A13: DSR-2026-012 | B13: 46188 | C13: Privacy mailbox | D13: Portability | E13: =IF($A13="","",IFERROR(VLOOKUP($D13,ReqTypes,2,FALSE),"?")) -> Art 20 | F13: =IF($A13="","",IFERROR(VLOOKUP($D13,ReqTypes,3,FALSE),"?")) -> Y | G13: Customer | H13: Online | I13: 46189 | J13: =IF(OR($A13="",$I13=""),"",IF(NETWORKDAYS($B13,$I13,Holidays)-1<=AckDays,"Y","N")) -> Y | K13: N | N13: =IF(OR($A13="",$K13<>"Y"),"",IF($L13="","Pending",IF($L13-$B13<=IDPromptDays,"Y","Check"))) | O13: =IF($A13="","",IF(OR($K13<>"Y",$L13=""),0,IF($M13="",MAX(0,ReportDate-$L13),$M13-$L13))) -> 0 | P13: =IF($A13="","",IF($F13<>"Y","n/a",WORKDAY(EDATE($B13,1)+$O13-1,1,Holidays))) -> 46218 | Q13: =IF($A13="","",$B13+$O13+InternalDays) -> 46203 | R13: N | T13: =IF(OR($A13="",$R13<>"Y"),"",IF($S13="","Missing",IF(AND($F13="Y",$S13<=$P13),"Y","Late"))) | U13: =IF($A13="","",IF($F13<>"Y",$Q13,IF(AND($R13="Y",$T13="Y"),WORKDAY(EDATE($B13,3)+$O13-1,1,Holidays),$P13))) -> 46218 | V13: IT | W13: Closed | X13: N | Y13: 46202 | Z13: =IF($A13="","",IF($Y13<>"",$Y13-$B13,ReportDate-$B13)) -> 14 | AA13: =IF(OR($A13="",$W13="Closed"),"",$U13-ReportDate) | AB13: =IF($A13="","",IF($W13="Closed",IF($Y13<=$U13,"Closed on time","Closed late"),IF($W13="Awaiting ID","Paused",IF($AA13<0,"Overdue",IF($AA13<=RedDays,"Red",IF($AA13<=AmberDays,"Amber","Green")))))) -> Closed on time | AC13: =IF(OR($A13="",$Y13=""),"",IF($Y13<=$U13,"Y","N")) -> Y | AD13: N | AF13: =IF($A13="","",IF(IF(OR($B13="",$C13="",$D13="",$V13="",$W13=""),"missing required field; ","")&IF(COUNTIF($A$2:$A$201,$A13)>1,"duplicate ID; ","")&IF(AND($B13<>"",$B13>ReportDate),"received after snapshot date; ","")&IF(AND($I13<>"",$B13<>"",$I13<$B13),"acknowledged before receipt; ","")&IF(AND($K13="Y",$L13="",$W13<>"Logged"),"ID requested date missing; ","")&IF(AND($L13<>"",$M13<>"",$M13<$L13),"ID dates out of order; ","")&IF(AND($K13<>"Y",OR($L13<>"",$W13="Awaiting ID")),"ID fields used but ID_Check_Needed is not Y; ","")&IF(AND($R13="Y",$S13=""),"extension notice date missing; ","")&IF(AND($R13<>"Y",$S13<>""),"notice date but Extended is not Y; ","")&IF(AND($W13="Closed",$Y13=""),"closed without response date; ","")&IF(AND($Y13<>"",$W13<>"Closed"),"response date but status not Closed; ","")&IF(AND($Y13<>"",$B13<>"",$Y13<$B13),"response before receipt; ","")&IF(AND($AD13="Y",$AE13=""),"exemption needs a reason in Notes; ","")="","OK","Check: "&IF(OR($B13="",$C13="",$D13="",$V13="",$W13=""),"missing required field; ","")&IF(COUNTIF($A$2:$A$201,$A13)>1,"duplicate ID; ","")&IF(AND($B13<>"",$B13>ReportDate),"received after snapshot date; ","")&IF(AND($I13<>"",$B13<>"",$I13<$B13),"acknowledged before receipt; ","")&IF(AND($K13="Y",$L13="",$W13<>"Logged"),"ID requested date missing; ","")&IF(AND($L13<>"",$M13<>"",$M13<$L13),"ID dates out of order; ","")&IF(AND($K13<>"Y",OR($L13<>"",$W13="Awaiting ID")),"ID fields used but ID_Check_Needed is not Y; ","")&IF(AND($R13="Y",$S13=""),"extension notice date missing; ","")&IF(AND($R13<>"Y",$S13<>""),"notice date but Extended is not Y; ","")&IF(AND($W13="Closed",$Y13=""),"closed without response date; ","")&IF(AND($Y13<>"",$W13<>"Closed"),"response date but status not Closed; ","")&IF(AND($Y13<>"",$B13<>"",$Y13<$B13),"response before receipt; ","")&IF(AND($AD13="Y",$AE13=""),"exemption needs a reason in Notes; ",""))) -> OK
A14: DSR-2026-013 | B14: 46191 | C14: Web form | D14: Access | E14: =IF($A14="","",IFERROR(VLOOKUP($D14,ReqTypes,2,FALSE),"?")) -> Art 15 | F14: =IF($A14="","",IFERROR(VLOOKUP($D14,ReqTypes,3,FALSE),"?")) -> Y | G14: Customer | H14: Loyalty & Marketing | I14: 46192 | J14: =IF(OR($A14="",$I14=""),"",IF(NETWORKDAYS($B14,$I14,Holidays)-1<=AckDays,"Y","N")) -> Y | K14: N | N14: =IF(OR($A14="",$K14<>"Y"),"",IF($L14="","Pending",IF($L14-$B14<=IDPromptDays,"Y","Check"))) | O14: =IF($A14="","",IF(OR($K14<>"Y",$L14=""),0,IF($M14="",MAX(0,ReportDate-$L14),$M14-$L14))) -> 0 | P14: =IF($A14="","",IF($F14<>"Y","n/a",WORKDAY(EDATE($B14,1)+$O14-1,1,Holidays))) -> 46223 | Q14: =IF($A14="","",$B14+$O14+InternalDays) -> 46206 | R14: N | T14: =IF(OR($A14="",$R14<>"Y"),"",IF($S14="","Missing",IF(AND($F14="Y",$S14<=$P14),"Y","Late"))) | U14: =IF($A14="","",IF($F14<>"Y",$Q14,IF(AND($R14="Y",$T14="Y"),WORKDAY(EDATE($B14,3)+$O14-1,1,Holidays),$P14))) -> 46223 | V14: Privacy Analyst | W14: Closed | X14: N | Y14: 46209 | Z14: =IF($A14="","",IF($Y14<>"",$Y14-$B14,ReportDate-$B14)) -> 18 | AA14: =IF(OR($A14="",$W14="Closed"),"",$U14-ReportDate) | AB14: =IF($A14="","",IF($W14="Closed",IF($Y14<=$U14,"Closed on time","Closed late"),IF($W14="Awaiting ID","Paused",IF($AA14<0,"Overdue",IF($AA14<=RedDays,"Red",IF($AA14<=AmberDays,"Amber","Green")))))) -> Closed on time | AC14: =IF(OR($A14="",$Y14=""),"",IF($Y14<=$U14,"Y","N")) -> Y | AD14: N | AF14: =IF($A14="","",IF(IF(OR($B14="",$C14="",$D14="",$V14="",$W14=""),"missing required field; ","")&IF(COUNTIF($A$2:$A$201,$A14)>1,"duplicate ID; ","")&IF(AND($B14<>"",$B14>ReportDate),"received after snapshot date; ","")&IF(AND($I14<>"",$B14<>"",$I14<$B14),"acknowledged before receipt; ","")&IF(AND($K14="Y",$L14="",$W14<>"Logged"),"ID requested date missing; ","")&IF(AND($L14<>"",$M14<>"",$M14<$L14),"ID dates out of order; ","")&IF(AND($K14<>"Y",OR($L14<>"",$W14="Awaiting ID")),"ID fields used but ID_Check_Needed is not Y; ","")&IF(AND($R14="Y",$S14=""),"extension notice date missing; ","")&IF(AND($R14<>"Y",$S14<>""),"notice date but Extended is not Y; ","")&IF(AND($W14="Closed",$Y14=""),"closed without response date; ","")&IF(AND($Y14<>"",$W14<>"Closed"),"response date but status not Closed; ","")&IF(AND($Y14<>"",$B14<>"",$Y14<$B14),"response before receipt; ","")&IF(AND($AD14="Y",$AE14=""),"exemption needs a reason in Notes; ","")="","OK","Check: "&IF(OR($B14="",$C14="",$D14="",$V14="",$W14=""),"missing required field; ","")&IF(COUNTIF($A$2:$A$201,$A14)>1,"duplicate ID; ","")&IF(AND($B14<>"",$B14>ReportDate),"received after snapshot date; ","")&IF(AND($I14<>"",$B14<>"",$I14<$B14),"acknowledged before receipt; ","")&IF(AND($K14="Y",$L14="",$W14<>"Logged"),"ID requested date missing; ","")&IF(AND($L14<>"",$M14<>"",$M14<$L14),"ID dates out of order; ","")&IF(AND($K14<>"Y",OR($L14<>"",$W14="Awaiting ID")),"ID fields used but ID_Check_Needed is not Y; ","")&IF(AND($R14="Y",$S14=""),"extension notice date missing; ","")&IF(AND($R14<>"Y",$S14<>""),"notice date but Extended is not Y; ","")&IF(AND($W14="Closed",$Y14=""),"closed without response date; ","")&IF(AND($Y14<>"",$W14<>"Closed"),"response date but status not Closed; ","")&IF(AND($Y14<>"",$B14<>"",$Y14<$B14),"response before receipt; ","")&IF(AND($AD14="Y",$AE14=""),"exemption needs a reason in Notes; ",""))) -> OK
A15: DSR-2026-014 | B15: 46197 | C15: Privacy mailbox | D15: Complaint | E15: =IF($A15="","",IFERROR(VLOOKUP($D15,ReqTypes,2,FALSE),"?")) -> n/a | F15: =IF($A15="","",IFERROR(VLOOKUP($D15,ReqTypes,3,FALSE),"?")) -> N | G15: Customer | H15: Customer Service | I15: 46198 | J15: =IF(OR($A15="",$I15=""),"",IF(NETWORKDAYS($B15,$I15,Holidays)-1<=AckDays,"Y","N")) -> Y | K15: N | N15: =IF(OR($A15="",$K15<>"Y"),"",IF($L15="","Pending",IF($L15-$B15<=IDPromptDays,"Y","Check"))) | O15: =IF($A15="","",IF(OR($K15<>"Y",$L15=""),0,IF($M15="",MAX(0,ReportDate-$L15),$M15-$L15))) -> 0 | P15: =IF($A15="","",IF($F15<>"Y","n/a",WORKDAY(EDATE($B15,1)+$O15-1,1,Holidays))) -> n/a | Q15: =IF($A15="","",$B15+$O15+InternalDays) -> 46212 | R15: N | T15: =IF(OR($A15="",$R15<>"Y"),"",IF($S15="","Missing",IF(AND($F15="Y",$S15<=$P15),"Y","Late"))) | U15: =IF($A15="","",IF($F15<>"Y",$Q15,IF(AND($R15="Y",$T15="Y"),WORKDAY(EDATE($B15,3)+$O15-1,1,Holidays),$P15))) -> 46212 | V15: Privacy Manager | W15: Closed | X15: N | Y15: 46209 | Z15: =IF($A15="","",IF($Y15<>"",$Y15-$B15,ReportDate-$B15)) -> 12 | AA15: =IF(OR($A15="",$W15="Closed"),"",$U15-ReportDate) | AB15: =IF($A15="","",IF($W15="Closed",IF($Y15<=$U15,"Closed on time","Closed late"),IF($W15="Awaiting ID","Paused",IF($AA15<0,"Overdue",IF($AA15<=RedDays,"Red",IF($AA15<=AmberDays,"Amber","Green")))))) -> Closed on time | AC15: =IF(OR($A15="",$Y15=""),"",IF($Y15<=$U15,"Y","N")) -> Y | AD15: N | AE15: Complaint about marketing frequency; not a statutory request | AF15: =IF($A15="","",IF(IF(OR($B15="",$C15="",$D15="",$V15="",$W15=""),"missing required field; ","")&IF(COUNTIF($A$2:$A$201,$A15)>1,"duplicate ID; ","")&IF(AND($B15<>"",$B15>ReportDate),"received after snapshot date; ","")&IF(AND($I15<>"",$B15<>"",$I15<$B15),"acknowledged before receipt; ","")&IF(AND($K15="Y",$L15="",$W15<>"Logged"),"ID requested date missing; ","")&IF(AND($L15<>"",$M15<>"",$M15<$L15),"ID dates out of order; ","")&IF(AND($K15<>"Y",OR($L15<>"",$W15="Awaiting ID")),"ID fields used but ID_Check_Needed is not Y; ","")&IF(AND($R15="Y",$S15=""),"extension notice date missing; ","")&IF(AND($R15<>"Y",$S15<>""),"notice date but Extended is not Y; ","")&IF(AND($W15="Closed",$Y15=""),"closed without response date; ","")&IF(AND($Y15<>"",$W15<>"Closed"),"response date but status not Closed; ","")&IF(AND($Y15<>"",$B15<>"",$Y15<$B15),"response before receipt; ","")&IF(AND($AD15="Y",$AE15=""),"exemption needs a reason in Notes; ","")="","OK","Check: "&IF(OR($B15="",$C15="",$D15="",$V15="",$W15=""),"missing required field; ","")&IF(COUNTIF($A$2:$A$201,$A15)>1,"duplicate ID; ","")&IF(AND($B15<>"",$B15>ReportDate),"received after snapshot date; ","")&IF(AND($I15<>"",$B15<>"",$I15<$B15),"acknowledged before receipt; ","")&IF(AND($K15="Y",$L15="",$W15<>"Logged"),"ID requested date missing; ","")&IF(AND($L15<>"",$M15<>"",$M15<$L15),"ID dates out of order; ","")&IF(AND($K15<>"Y",OR($L15<>"",$W15="Awaiting ID")),"ID fields used but ID_Check_Needed is not Y; ","")&IF(AND($R15="Y",$S15=""),"extension notice date missing; ","")&IF(AND($R15<>"Y",$S15<>""),"notice date but Extended is not Y; ","")&IF(AND($W15="Closed",$Y15=""),"closed without response date; ","")&IF(AND($Y15<>"",$W15<>"Closed"),"response date but status not Closed; ","")&IF(AND($Y15<>"",$B15<>"",$Y15<$B15),"response before receipt; ","")&IF(AND($AD15="Y",$AE15=""),"exemption needs a reason in Notes; ",""))) -> OK
A16: DSR-2026-015 | B16: 46202 | C16: Privacy mailbox | D16: Access | E16: =IF($A16="","",IFERROR(VLOOKUP($D16,ReqTypes,2,FALSE),"?")) -> Art 15 | F16: =IF($A16="","",IFERROR(VLOOKUP($D16,ReqTypes,3,FALSE),"?")) -> Y | G16: Former employee | H16: HR | I16: 46203 | J16: =IF(OR($A16="",$I16=""),"",IF(NETWORKDAYS($B16,$I16,Holidays)-1<=AckDays,"Y","N")) -> Y | K16: Y | L16: 46203 | M16: 46206 | N16: =IF(OR($A16="",$K16<>"Y"),"",IF($L16="","Pending",IF($L16-$B16<=IDPromptDays,"Y","Check"))) -> Y | O16: =IF($A16="","",IF(OR($K16<>"Y",$L16=""),0,IF($M16="",MAX(0,ReportDate-$L16),$M16-$L16))) -> 3 | P16: =IF($A16="","",IF($F16<>"Y","n/a",WORKDAY(EDATE($B16,1)+$O16-1,1,Holidays))) -> 46238 | Q16: =IF($A16="","",$B16+$O16+InternalDays) -> 46220 | R16: Y | S16: 46222 | T16: =IF(OR($A16="",$R16<>"Y"),"",IF($S16="","Missing",IF(AND($F16="Y",$S16<=$P16),"Y","Late"))) -> Y | U16: =IF($A16="","",IF($F16<>"Y",$Q16,IF(AND($R16="Y",$T16="Y"),WORKDAY(EDATE($B16,3)+$O16-1,1,Holidays),$P16))) -> 46297 | V16: HR | W16: Closed | X16: Y | Y16: 46272 | Z16: =IF($A16="","",IF($Y16<>"",$Y16-$B16,ReportDate-$B16)) -> 70 | AA16: =IF(OR($A16="",$W16="Closed"),"",$U16-ReportDate) | AB16: =IF($A16="","",IF($W16="Closed",IF($Y16<=$U16,"Closed on time","Closed late"),IF($W16="Awaiting ID","Paused",IF($AA16<0,"Overdue",IF($AA16<=RedDays,"Red",IF($AA16<=AmberDays,"Amber","Green")))))) -> Closed on time | AC16: =IF(OR($A16="",$Y16=""),"",IF($Y16<=$U16,"Y","N")) -> Y | AD16: Y | AE16: Complex: 4 years of emails. Extension notified with reasons. Legal privilege withheld, schedule RS-015 | AF16: =IF($A16="","",IF(IF(OR($B16="",$C16="",$D16="",$V16="",$W16=""),"missing required field; ","")&IF(COUNTIF($A$2:$A$201,$A16)>1,"duplicate ID; ","")&IF(AND($B16<>"",$B16>ReportDate),"received after snapshot date; ","")&IF(AND($I16<>"",$B16<>"",$I16<$B16),"acknowledged before receipt; ","")&IF(AND($K16="Y",$L16="",$W16<>"Logged"),"ID requested date missing; ","")&IF(AND($L16<>"",$M16<>"",$M16<$L16),"ID dates out of order; ","")&IF(AND($K16<>"Y",OR($L16<>"",$W16="Awaiting ID")),"ID fields used but ID_Check_Needed is not Y; ","")&IF(AND($R16="Y",$S16=""),"extension notice date missing; ","")&IF(AND($R16<>"Y",$S16<>""),"notice date but Extended is not Y; ","")&IF(AND($W16="Closed",$Y16=""),"closed without response date; ","")&IF(AND($Y16<>"",$W16<>"Closed"),"response date but status not Closed; ","")&IF(AND($Y16<>"",$B16<>"",$Y16<$B16),"response before receipt; ","")&IF(AND($AD16="Y",$AE16=""),"exemption needs a reason in Notes; ","")="","OK","Check: "&IF(OR($B16="",$C16="",$D16="",$V16="",$W16=""),"missing required field; ","")&IF(COUNTIF($A$2:$A$201,$A16)>1,"duplicate ID; ","")&IF(AND($B16<>"",$B16>ReportDate),"received after snapshot date; ","")&IF(AND($I16<>"",$B16<>"",$I16<$B16),"acknowledged before receipt; ","")&IF(AND($K16="Y",$L16="",$W16<>"Logged"),"ID requested date missing; ","")&IF(AND($L16<>"",$M16<>"",$M16<$L16),"ID dates out of order; ","")&IF(AND($K16<>"Y",OR($L16<>"",$W16="Awaiting ID")),"ID fields used but ID_Check_Needed is not Y; ","")&IF(AND($R16="Y",$S16=""),"extension notice date missing; ","")&IF(AND($R16<>"Y",$S16<>""),"notice date but Extended is not Y; ","")&IF(AND($W16="Closed",$Y16=""),"closed without response date; ","")&IF(AND($Y16<>"",$W16<>"Closed"),"response date but status not Closed; ","")&IF(AND($Y16<>"",$B16<>"",$Y16<$B16),"response before receipt; ","")&IF(AND($AD16="Y",$AE16=""),"exemption needs a reason in Notes; ",""))) -> OK
